Workbook

Sheet 1-Players
A1: Jugador_ID | B1: Equipo | C1: Dorsal | D1: Nombre | E1: Posición | F1: Titular
A2: JM00 | B2: MANRESA | C2: 0 | D2: Kaodirichi Akobundu | E2: P | F2: NO
A3: JM02 | B3: MANRESA | C3: 2 | D3: Hugo Benítez | E3: B | F3: SI
A4: JM08 | B4: MANRESA | C4: 8 | D4: Álex Reyes | E4: A | F4: SI
A5: JM11 | B5: MANRESA | C5: 11 | D5: Agustín Ubal | E5: A | F5: NO
A6: JM12 | B6: MANRESA | C6: 12 | D6: Marcis Steinbergs | E6: AP | F6: SI
A7: JM18 | B7: MANRESA | C7: 18 | D7: Gustav Knudsen | E7: A | F7: NO
A8: JM19 | B8: MANRESA | C8: 19 | D8: Louis Olinde | E8: AP | F8: NO
A9: JM32 | B9: MANRESA | C9: 32 | D9: Retin Obasohan | E9: B | F9: SI
A10: JM33 | B10: MANRESA | C10: 33 | D10: Grant Golden | E10: P | F10: SI
A11: JM47 | B11: MANRESA | C11: 47 | D11: Archange Izaw Bolavie | E11: P | F11: NO
A12: JM55 | B12: MANRESA | C12: 55 | D12: Dani Pérez | E12: B | F12: NO
A13: JM99 | B13: MANRESA | C13: 99 | D13: Alfonso Plummer | E13: E | F13: NO
... A25: JL25 | B25: LLEIDA | C25: 25 | D25: Cameron Krutwig | E25: P | F25: NO
A26: MAN | D26: TEAM - Manresa
A27: LLE | D27: TEAM - Lleida

Sheet 2-DATASET
A1: Cuarto | B1: Evento_ID | C1: Tiempo | D1: Minuto | E1: Segundo | F1: Equipo | G1: Jugador_ID | H1: Jugador | J1: Resultado | K1: Tiro_Intentado | L1: Anotado (0/1) | M1: Puntos_Conseguidos | N1: Tipo_Tiro | O1: Zona_de_Tiro | P1: Tiempo_Posesion_Restante | Q1: Contestado (S/N) | R1: Asistido (S/N) | S1: Rebote_ofensivo | T1: Rebote_defensivo | U1: Asistencia | V1: Pérdida | W1: Recuperacion | X1: Tapón_realizado | Y1: Tapón_recibido | Z1: Falta_Cometida | AA1: Falta_Recibida | AB1: Tiempo_Entra | AC1: Tiempo_Sale | AD1: Tiempo_Pista_Sustituciones | AE1: Tiempo_Pista_Completo | AF1: PickAndRoll (S/N)
A2: 1 | B2: 1 | C2: 0.0069444444 | D2: =MINUTE(C2) -> 10 | E2: =SECOND(C2) -> 0 | F2: LLEIDA | G2: JL12 | H2: =_xlfn.XLOOKUP(G2,'1-Players'!$A$2:$A$27,'1-Players'!$D$2:$D$27,"") -> Atoumane Diagne | I2: Starting lineup | K2: {=IFERROR(_xlfn.IFS(I2="Free Throw",1,I2="2-Point Shot",2,I2="Dunk",2,I2="3-Point Shot",3),"")} | L2: {=IFERROR(_xlfn.IFS(J2="Made",1,J2="Missed",0),"")} | M2: =IFERROR(K2*L2,"") | R2: =IF(J2<>"Made","",IF(I3="Assist","S","N")) | S2: {=IFERROR(_xlfn.IFS(I2="Offensive Rebound",1),"")} | T2: {=IFERROR(_xlfn.IFS(I2="Defensive Rebound",1),"")} | U2: {=IFERROR(_xlfn.IFS(I2="Assist",1),"")} | V2: {=IFERROR(_xlfn.IFS(I2="Turnover",1),"")} | W2: {=IFERROR(_xlfn.IFS(I2="Steal",1),"")} | X2: {=IFERROR(_xlfn.IFS(I2="Block",1),"")} | Y2: {=IFERROR(_xlfn.IFS(I2="Block Received",1),"")} | Z2: {=IFERROR(_xlfn.IFS(I2="Foul",1,I2="Foul Technical",1,I2="Offensive Foul",1),"")} | AA2: {=IFERROR(_xlfn.IFS(I2="Foul Received",1),"")} | AB2: {=IFERROR(_xlfn.IFS(I2="Starting lineup",C2,I2="Substitution - In",C2),"")} -> 0.0069444444 | AC2: {=IFERROR(_xlfn.IFS(I2="Finishing lineup",C2,I2="Substitution - Out",C2),"")} | AD2: {=IF(AC2<>"",LOOKUP(2,1/((G1:G$2=G2)*(AB1:AB$2<>"")),AB1:AB$2)-AC2,"")} | AE2: {=IF(AC2<>"",LOOKUP(2,1/((G1:G$2=G2)*(AB1:AB$2<>"")),AB1:AB$2)-AC2,"")}
A3: 1 | B3: 2 | C3: 0.0069444444 | D3: =MINUTE(C3) -> 10 | E3: =SECOND(C3) -> 0 | F3: LLEIDA | G3: JL14 | H3: =_xlfn.XLOOKUP(G3,'1-Players'!$A$2:$A$27,'1-Players'!$D$2:$D$27,"") -> Mikel Sanz | I3: Starting lineup | K3: {=IFERROR(_xlfn.IFS(I3="Free Throw",1,I3="2-Point Shot",2,I3="Dunk",2,I3="3-Point Shot",3),"")} | L3: {=IFERROR(_xlfn.IFS(J3="Made",1,J3="Missed",0),"")} | M3: =IFERROR(K3*L3,"") | R3: =IF(J3<>"Made","",IF(I4="Assist","S","N")) | S3: {=IFERROR(_xlfn.IFS(I3="Offensive Rebound",1),"")} | T3: {=IFERROR(_xlfn.IFS(I3="Defensive Rebound",1),"")} | U3: {=IFERROR(_xlfn.IFS(I3="Assist",1),"")} | V3: {=IFERROR(_xlfn.IFS(I3="Turnover",1),"")} | W3: {=IFERROR(_xlfn.IFS(I3="Steal",1),"")} | X3: {=IFERROR(_xlfn.IFS(I3="Block",1),"")} | Y3: {=IFERROR(_xlfn.IFS(I3="Block Received",1),"")} | Z3: {=IFERROR(_xlfn.IFS(I3="Foul",1,I3="Foul Technical",1,I3="Offensive Foul",1),"")} | AA3: {=IFERROR(_xlfn.IFS(I3="Foul Received",1),"")} | AB3: {=IFERROR(_xlfn.IFS(I3="Starting lineup",C3,I3="Substitution - In",C3),"")} -> 0.0069444444 | AC3: {=IFERROR(_xlfn.IFS(I3="Finishing lineup",C3,I3="Substitution - Out",C3),"")} | AD3: {=IF(AC3<>"",LOOKUP(2,1/((G2:G$2=G3)*(AB2:AB$2<>"")),AB2:AB$2)-AC3,"")} | AE3: {=IF(AC3<>"",LOOKUP(2,1/((G2:G$2=G3)*(AB2:AB$2<>"")),AB2:AB$2)-AC3,"")}
A4: 1 | B4: 3 | C4: 0.0069444444 | D4: =MINUTE(C4) -> 10 | E4: =SECOND(C4) -> 0 | F4: LLEIDA | G4: JL01 | H4: =_xlfn.XLOOKUP(G4,'1-Players'!$A$2:$A$27,'1-Players'!$D$2:$D$27,"") -> James Batemon | I4: Starting lineup | K4: {=IFERROR(_xlfn.IFS(I4="Free Throw",1,I4="2-Point Shot",2,I4="Dunk",2,I4="3-Point Shot",3),"")} | L4: {=IFERROR(_xlfn.IFS(J4="Made",1,J4="Missed",0),"")} | M4: =IFERROR(K4*L4,"") | R4: =IF(J4<>"Made","",IF(I5="Assist","S","N")) | S4: {=IFERROR(_xlfn.IFS(I4="Offensive Rebound",1),"")} | T4: {=IFERROR(_xlfn.IFS(I4="Defensive Rebound",1),"")} | U4: {=IFERROR(_xlfn.IFS(I4="Assist",1),"")} | V4: {=IFERROR(_xlfn.IFS(I4="Turnover",1),"")} | W4: {=IFERROR(_xlfn.IFS(I4="Steal",1),"")} | X4: {=IFERROR(_xlfn.IFS(I4="Block",1),"")} | Y4: {=IFERROR(_xlfn.IFS(I4="Block Received",1),"")} | Z4: {=IFERROR(_xlfn.IFS(I4="Foul",1,I4="Foul Technical",1,I4="Offensive Foul",1),"")} | AA4: {=IFERROR(_xlfn.IFS(I4="Foul Received",1),"")} | AB4: {=IFERROR(_xlfn.IFS(I4="Starting lineup",C4,I4="Substitution - In",C4),"")} -> 0.0069444444 | AC4: {=IFERROR(_xlfn.IFS(I4="Finishing lineup",C4,I4="Substitution - Out",C4),"")} | AD4: {=IF(AC4<>"",LOOKUP(2,1/((G$2:G3=G4)*(AB$2:AB3<>"")),AB$2:AB3)-AC4,"")} | AE4: {=IF(AC4<>"",LOOKUP(2,1/((G$2:G3=G4)*(AB$2:AB3<>"")),AB$2:AB3)-AC4,"")}
A5: 1 | B5: 4 | C5: 0.0069444444 | D5: =MINUTE(C5) -> 10 | E5: =SECOND(C5) -> 0 | F5: LLEIDA | G5: JL04 | H5: =_xlfn.XLOOKUP(G5,'1-Players'!$A$2:$A$27,'1-Players'!$D$2:$D$27,"") -> Caleb Agada | I5: Starting lineup | K5: {=IFERROR(_xlfn.IFS(I5="Free Throw",1,I5="2-Point Shot",2,I5="Dunk",2,I5="3-Point Shot",3),"")} | L5: {=IFERROR(_xlfn.IFS(J5="Made",1,J5="Missed",0),"")} | M5: =IFERROR(K5*L5,"") | R5: =IF(J5<>"Made","",IF(I6="Assist","S","N")) | S5: {=IFERROR(_xlfn.IFS(I5="Offensive Rebound",1),"")} | T5: {=IFERROR(_xlfn.IFS(I5="Defensive Rebound",1),"")} | U5: {=IFERROR(_xlfn.IFS(I5="Assist",1),"")} | V5: {=IFERROR(_xlfn.IFS(I5="Turnover",1),"")} | W5: {=IFERROR(_xlfn.IFS(I5="Steal",1),"")} | X5: {=IFERROR(_xlfn.IFS(I5="Block",1),"")} | Y5: {=IFERROR(_xlfn.IFS(I5="Block Received",1),"")} | Z5: {=IFERROR(_xlfn.IFS(I5="Foul",1,I5="Foul Technical",1,I5="Offensive Foul",1),"")} | AA5: {=IFERROR(_xlfn.IFS(I5="Foul Received",1),"")} | AB5: {=IFERROR(_xlfn.IFS(I5="Starting lineup",C5,I5="Substitution - In",C5),"")} -> 0.0069444444 | AC5: {=IFERROR(_xlfn.IFS(I5="Finishing lineup",C5,I5="Substitution - Out",C5),"")} | AD5: {=IF(AC5<>"",LOOKUP(2,1/((G$2:G4=G5)*(AB$2:AB4<>"")),AB$2:AB4)-AC5,"")} | AE5: {=IF(AC5<>"",LOOKUP(2,1/((G$2:G4=G5)*(AB$2:AB4<>"")),AB$2:AB4)-AC5,"")}
A6: 1 | B6: 5 | C6: 0.0069444444 | D6: =MINUTE(C6) -> 10 | E6: =SECOND(C6) -> 0 | F6: LLEIDA | G6: JL03 | H6: =_xlfn.XLOOKUP(G6,'1-Players'!$A$2:$A$27,'1-Players'!$D$2:$D$27,"") -> Melvin Ejim | I6: Starting lineup | K6: {=IFERROR(_xlfn.IFS(I6="Free Throw",1,I6="2-Point Shot",2,I6="Dunk",2,I6="3-Point Shot",3),"")} | L6: {=IFERROR(_xlfn.IFS(J6="Made",1,J6="Missed",0),"")} | M6: =IFERROR(K6*L6,"") | R6: =IF(J6<>"Made","",IF(I7="Assist","S","N")) | S6: {=IFERROR(_xlfn.IFS(I6="Offensive Rebound",1),"")} | T6: {=IFERROR(_xlfn.IFS(I6="Defensive Rebound",1),"")} | U6: {=IFERROR(_xlfn.IFS(I6="Assist",1),"")} | V6: {=IFERROR(_xlfn.IFS(I6="Turnover",1),"")} | W6: {=IFERROR(_xlfn.IFS(I6="Steal",1),"")} | X6: {=IFERROR(_xlfn.IFS(I6="Block",1),"")} | Y6: {=IFERROR(_xlfn.IFS(I6="Block Received",1),"")} | Z6: {=IFERROR(_xlfn.IFS(I6="Foul",1,I6="Foul Technical",1,I6="Offensive Foul",1),"")} | AA6: {=IFERROR(_xlfn.IFS(I6="Foul Received",1),"")} | AB6: {=IFERROR(_xlfn.IFS(I6="Starting lineup",C6,I6="Substitution - In",C6),"")} -> 0.0069444444 | AC6: {=IFERROR(_xlfn.IFS(I6="Finishing lineup",C6,I6="Substitution - Out",C6),"")} | AD6: {=IF(AC6<>"",LOOKUP(2,1/((G$2:G5=G6)*(AB$2:AB5<>"")),AB$2:AB5)-AC6,"")} | AE6: {=IF(AC6<>"",LOOKUP(2,1/((G$2:G5=G6)*(AB$2:AB5<>"")),AB$2:AB5)-AC6,"")}
A7: 1 | B7: 6 | C7: 0.0069444444 | D7: =MINUTE(C7) -> 10 | E7: =SECOND(C7) -> 0 | F7: MANRESA | G7: JM08 | H7: =_xlfn.XLOOKUP(G7,'1-Players'!$A$2:$A$27,'1-Players'!$D$2:$D$27,"") -> Álex Reyes | I7: Starting lineup | K7: {=IFERROR(_xlfn.IFS(I7="Free Throw",1,I7="2-Point Shot",2,I7="Dunk",2,I7="3-Point Shot",3),"")} | L7: {=IFERROR(_xlfn.IFS(J7="Made",1,J7="Missed",0),"")} | M7: =IFERROR(K7*L7,"") | R7: =IF(J7<>"Made","",IF(I8="Assist","S","N")) | S7: {=IFERROR(_xlfn.IFS(I7="Offensive Rebound",1),"")} | T7: {=IFERROR(_xlfn.IFS(I7="Defensive Rebound",1),"")} | U7: {=IFERROR(_xlfn.IFS(I7="Assist",1),"")} | V7: {=IFERROR(_xlfn.IFS(I7="Turnover",1),"")} | W7: {=IFERROR(_xlfn.IFS(I7="Steal",1),"")} | X7: {=IFERROR(_xlfn.IFS(I7="Block",1),"")} | Y7: {=IFERROR(_xlfn.IFS(I7="Block Received",1),"")} | Z7: {=IFERROR(_xlfn.IFS(I7="Foul",1,I7="Foul Technical",1,I7="Offensive Foul",1),"")} | AA7: {=IFERROR(_xlfn.IFS(I7="Foul Received",1),"")} | AB7: {=IFERROR(_xlfn.IFS(I7="Starting lineup",C7,I7="Substitution - In",C7),"")} -> 0.0069444444 | AC7: {=IFERROR(_xlfn.IFS(I7="Finishing lineup",C7,I7="Substitution - Out",C7),"")} | AD7: {=IF(AC7<>"",LOOKUP(2,1/((G$2:G6=G7)*(AB$2:AB6<>"")),AB$2:AB6)-AC7,"")} | AE7: {=IF(AC7<>"",LOOKUP(2,1/((G$2:G6=G7)*(AB$2:AB6<>"")),AB$2:AB6)-AC7,"")}
A8: 1 | B8: 7 | C8: 0.0069444444 | D8: =MINUTE(C8) -> 10 | E8: =SECOND(C8) -> 0 | F8: MANRESA | G8: JM33 | H8: =_xlfn.XLOOKUP(G8,'1-Players'!$A$2:$A$27,'1-Players'!$D$2:$D$27,"") -> Grant Golden | I8: Starting lineup | K8: {=IFERROR(_xlfn.IFS(I8="Free Throw",1,I8="2-Point Shot",2,I8="Dunk",2,I8="3-Point Shot",3),"")} | L8: {=IFERROR(_xlfn.IFS(J8="Made",1,J8="Missed",0),"")} | M8: =IFERROR(K8*L8,"") | R8: =IF(J8<>"Made","",IF(I9="Assist","S","N")) | S8: {=IFERROR(_xlfn.IFS(I8="Offensive Rebound",1),"")} | T8: {=IFERROR(_xlfn.IFS(I8="Defensive Rebound",1),"")} | U8: {=IFERROR(_xlfn.IFS(I8="Assist",1),"")} | V8: {=IFERROR(_xlfn.IFS(I8="Turnover",1),"")} | W8: {=IFERROR(_xlfn.IFS(I8="Steal",1),"")} | X8: {=IFERROR(_xlfn.IFS(I8="Block",1),"")} | Y8: {=IFERROR(_xlfn.IFS(I8="Block Received",1),"")} | Z8: {=IFERROR(_xlfn.IFS(I8="Foul",1,I8="Foul Technical",1,I8="Offensive Foul",1),"")} | AA8: {=IFERROR(_xlfn.IFS(I8="Foul Received",1),"")} | AB8: {=IFERROR(_xlfn.IFS(I8="Starting lineup",C8,I8="Substitution - In",C8),"")} -> 0.0069444444 | AC8: {=IFERROR(_xlfn.IFS(I8="Finishing lineup",C8,I8="Substitution - Out",C8),"")} | AD8: {=IF(AC8<>"",LOOKUP(2,1/((G$2:G7=G8)*(AB$2:AB7<>"")),AB$2:AB7)-AC8,"")} | AE8: {=IF(AC8<>"",LOOKUP(2,1/((G$2:G7=G8)*(AB$2:AB7<>"")),AB$2:AB7)-AC8,"")}
A9: 1 | B9: 8 | C9: 0.0069444444 | D9: =MINUTE(C9) -> 10 | E9: =SECOND(C9) -> 0 | F9: MANRESA | G9: JM02 | H9: =_xlfn.XLOOKUP(G9,'1-Players'!$A$2:$A$27,'1-Players'!$D$2:$D$27,"") -> Hugo Benítez | I9: Starting lineup | K9: {=IFERROR(_xlfn.IFS(I9="Free Throw",1,I9="2-Point Shot",2,I9="Dunk",2,I9="3-Point Shot",3),"")} | L9: {=IFERROR(_xlfn.IFS(J9="Made",1,J9="Missed",0),"")} | M9: =IFERROR(K9*L9,"") | R9: =IF(J9<>"Made","",IF(I10="Assist","S","N")) | S9: {=IFERROR(_xlfn.IFS(I9="Offensive Rebound",1),"")} | T9: {=IFERROR(_xlfn.IFS(I9="Defensive Rebound",1),"")} | U9: {=IFERROR(_xlfn.IFS(I9="Assist",1),"")} | V9: {=IFERROR(_xlfn.IFS(I9="Turnover",1),"")} | W9: {=IFERROR(_xlfn.IFS(I9="Steal",1),"")} | X9: {=IFERROR(_xlfn.IFS(I9="Block",1),"")} | Y9: {=IFERROR(_xlfn.IFS(I9="Block Received",1),"")} | Z9: {=IFERROR(_xlfn.IFS(I9="Foul",1,I9="Foul Technical",1,I9="Offensive Foul",1),"")} | AA9: {=IFERROR(_xlfn.IFS(I9="Foul Received",1),"")} | AB9: {=IFERROR(_xlfn.IFS(I9="Starting lineup",C9,I9="Substitution - In",C9),"")} -> 0.0069444444 | AC9: {=IFERROR(_xlfn.IFS(I9="Finishing lineup",C9,I9="Substitution - Out",C9),"")} | AD9: {=IF(AC9<>"",LOOKUP(2,1/((G$2:G8=G9)*(AB$2:AB8<>"")),AB$2:AB8)-AC9,"")} | AE9: {=IF(AC9<>"",LOOKUP(2,1/((G$2:G8=G9)*(AB$2:AB8<>"")),AB$2:AB8)-AC9,"")}
A10: 1 | B10: 9 | C10: 0.0069444444 | D10: =MINUTE(C10) -> 10 | E10: =SECOND(C10) -> 0 | F10: MANRESA | G10: JM32 | H10: =_xlfn.XLOOKUP(G10,'1-Players'!$A$2:$A$27,'1-Players'!$D$2:$D$27,"") -> Retin Obasohan | I10: Starting lineup | K10: {=IFERROR(_xlfn.IFS(I10="Free Throw",1,I10="2-Point Shot",2,I10="Dunk",2,I10="3-Point Shot",3),"")} | L10: {=IFERROR(_xlfn.IFS(J10="Made",1,J10="Missed",0),"")} | M10: =IFERROR(K10*L10,"") | R10: =IF(J10<>"Made","",IF(I11="Assist","S","N")) | S10: {=IFERROR(_xlfn.IFS(I10="Offensive Rebound",1),"")} | T10: {=IFERROR(_xlfn.IFS(I10="Defensive Rebound",1),"")} | U10: {=IFERROR(_xlfn.IFS(I10="Assist",1),"")} | V10: {=IFERROR(_xlfn.IFS(I10="Turnover",1),"")} | W10: {=IFERROR(_xlfn.IFS(I10="Steal",1),"")} | X10: {=IFERROR(_xlfn.IFS(I10="Block",1),"")} | Y10: {=IFERROR(_xlfn.IFS(I10="Block Received",1),"")} | Z10: {=IFERROR(_xlfn.IFS(I10="Foul",1,I10="Foul Technical",1,I10="Offensive Foul",1),"")} | AA10: {=IFERROR(_xlfn.IFS(I10="Foul Received",1),"")} | AB10: {=IFERROR(_xlfn.IFS(I10="Starting lineup",C10,I10="Substitution - In",C10),"")} -> 0.0069444444 | AC10: {=IFERROR(_xlfn.IFS(I10="Finishing lineup",C10,I10="Substitution - Out",C10),"")} | AD10: {=IF(AC10<>"",LOOKUP(2,1/((G$2:G9=G10)*(AB$2:AB9<>"")),AB$2:AB9)-AC10,"")} | AE10: {=IF(AC10<>"",LOOKUP(2,1/((G$2:G9=G10)*(AB$2:AB9<>"")),AB$2:AB9)-AC10,"")}
A11: 1 | B11: 10 | C11: 0.0069444444 | D11: =MINUTE(C11) -> 10 | E11: =SECOND(C11) -> 0 | F11: MANRESA | G11: JM12 | H11: =_xlfn.XLOOKUP(G11,'1-Players'!$A$2:$A$27,'1-Players'!$D$2:$D$27,"") -> Marcis Steinbergs | I11: Starting lineup | K11: {=IFERROR(_xlfn.IFS(I11="Free Throw",1,I11="2-Point Shot",2,I11="Dunk",2,I11="3-Point Shot",3),"")} | L11: {=IFERROR(_xlfn.IFS(J11="Made",1,J11="Missed",0),"")} | M11: =IFERROR(K11*L11,"") | R11: =IF(J11<>"Made","",IF(I12="Assist","S","N")) | S11: {=IFERROR(_xlfn.IFS(I11="Offensive Rebound",1),"")} | T11: {=IFERROR(_xlfn.IFS(I11="Defensive Rebound",1),"")} | U11: {=IFERROR(_xlfn.IFS(I11="Assist",1),"")} | V11: {=IFERROR(_xlfn.IFS(I11="Turnover",1),"")} | W11: {=IFERROR(_xlfn.IFS(I11="Steal",1),"")} | X11: {=IFERROR(_xlfn.IFS(I11="Block",1),"")} | Y11: {=IFERROR(_xlfn.IFS(I11="Block Received",1),"")} | Z11: {=IFERROR(_xlfn.IFS(I11="Foul",1,I11="Foul Technical",1,I11="Offensive Foul",1),"")} | AA11: {=IFERROR(_xlfn.IFS(I11="Foul Received",1),"")} | AB11: {=IFERROR(_xlfn.IFS(I11="Starting lineup",C11,I11="Substitution - In",C11),"")} -> 0.0069444444 | AC11: {=IFERROR(_xlfn.IFS(I11="Finishing lineup",C11,I11="Substitution - Out",C11),"")} | AD11: {=IF(AC11<>"",LOOKUP(2,1/((G$2:G10=G11)*(AB$2:AB10<>"")),AB$2:AB10)-AC11,"")} | AE11: {=IF(AC11<>"",LOOKUP(2,1/((G$2:G10=G11)*(AB$2:AB10<>"")),AB$2:AB10)-AC11,"")}
A12: 1 | B12: 11 | C12: 0.0069444444 | D12: =MINUTE(C12) -> 10 | E12: =SECOND(C12) -> 0 | F12: MANRESA | G12: JM33 | H12: =_xlfn.XLOOKUP(G12,'1-Players'!$A$2:$A$27,'1-Players'!$D$2:$D$27,"") -> Grant Golden | I12: Jump ball won | K12: {=IFERROR(_xlfn.IFS(I12="Free Throw",1,I12="2-Point Shot",2,I12="Dunk",2,I12="3-Point Shot",3),"")} | L12: {=IFERROR(_xlfn.IFS(J12="Made",1,J12="Missed",0),"")} | M12: =IFERROR(K12*L12,"") | R12: =IF(J12<>"Made","",IF(I13="Assist","S","N")) | S12: {=IFERROR(_xlfn.IFS(I12="Offensive Rebound",1),"")} | T12: {=IFERROR(_xlfn.IFS(I12="Defensive Rebound",1),"")} | U12: {=IFERROR(_xlfn.IFS(I12="Assist",1),"")} | V12: {=IFERROR(_xlfn.IFS(I12="Turnover",1),"")} | W12: {=IFERROR(_xlfn.IFS(I12="Steal",1),"")} | X12: {=IFERROR(_xlfn.IFS(I12="Block",1),"")} | Y12: {=IFERROR(_xlfn.IFS(I12="Block Received",1),"")} | Z12: {=IFERROR(_xlfn.IFS(I12="Foul",1,I12="Foul Technical",1,I12="Offensive Foul",1),"")} | AA12: {=IFERROR(_xlfn.IFS(I12="Foul Received",1),"")} | AB12: {=IFERROR(_xlfn.IFS(I12="Starting lineup",C12,I12="Substitution - In",C12),"")} | AC12: {=IFERROR(_xlfn.IFS(I12="Finishing lineup",C12,I12="Substitution - Out",C12),"")} | AD12: {=IF(AC12<>"",LOOKUP(2,1/((G$2:G11=G12)*(AB$2:AB11<>"")),AB$2:AB11)-AC12,"")} | AE12: {=IF(AC12<>"",LOOKUP(2,1/((G$2:G11=G12)*(AB$2:AB11<>"")),AB$2:AB11)-AC12,"")}
A13: 1 | B13: 12 | C13: 0.0069444444 | D13: =MINUTE(C13) -> 10 | E13: =SECOND(C13) -> 0 | F13: LLEIDA | G13: JL12 | H13: =_xlfn.XLOOKUP(G13,'1-Players'!$A$2:$A$27,'1-Players'!$D$2:$D$27,"") -> Atoumane Diagne | I13: Jump ball lost | K13: {=IFERROR(_xlfn.IFS(I13="Free Throw",1,I13="2-Point Shot",2,I13="Dunk",2,I13="3-Point Shot",3),"")} | L13: {=IFERROR(_xlfn.IFS(J13="Made",1,J13="Missed",0),"")} | M13: =IFERROR(K13*L13,"") | R13: =IF(J13<>"Made","",IF(I14="Assist","S","N")) | S13: {=IFERROR(_xlfn.IFS(I13="Offensive Rebound",1),"")} | T13: {=IFERROR(_xlfn.IFS(I13="Defensive Rebound",1),"")} | U13: {=IFERROR(_xlfn.IFS(I13="Assist",1),"")} | V13: {=IFERROR(_xlfn.IFS(I13="Turnover",1),"")} | W13: {=IFERROR(_xlfn.IFS(I13="Steal",1),"")} | X13: {=IFERROR(_xlfn.IFS(I13="Block",1),"")} | Y13: {=IFERROR(_xlfn.IFS(I13="Block Received",1),"")} | Z13: {=IFERROR(_xlfn.IFS(I13="Foul",1,I13="Foul Technical",1,I13="Offensive Foul",1),"")} | AA13: {=IFERROR(_xlfn.IFS(I13="Foul Received",1),"")} | AB13: {=IFERROR(_xlfn.IFS(I13="Starting lineup",C13,I13="Substitution - In",C13),"")} | AC13: {=IFERROR(_xlfn.IFS(I13="Finishing lineup",C13,I13="Substitution - Out",C13),"")} | AD13: {=IF(AC13<>"",LOOKUP(2,1/((G$2:G12=G13)*(AB$2:AB12<>"")),AB$2:AB12)-AC13,"")} | AE13: {=IF(AC13<>"",LOOKUP(2,1/((G$2:G12=G13)*(AB$2:AB12<>"")),AB$2:AB12)-AC13,"")}
A14: 1 | B14: 13 | C14: 0.006712963 | D14: =MINUTE(C14) -> 9 | E14: =SECOND(C14) -> 40 | F14: MANRESA | G14: JM32 | H14: =_xlfn.XLOOKUP(G14,'1-Players'!$A$2:$A$27,'1-Players'!$D$2:$D$27,"") -> Retin Obasohan | I14: 2-Point Shot | J14: Made | K14: {=IFERROR(_xlfn.IFS(I14="Free Throw",1,I14="2-Point Shot",2,I14="Dunk",2,I14="3-Point Shot",3),"")} -> 2 | L14: {=IFERROR(_xlfn.IFS(J14="Made",1,J14="Missed",0),"")} -> 1 | M14: =IFERROR(K14*L14,"") -> 2 | N14: Pull-up | O14: MC | P14: 5 | Q14: S | R14: =IF(J14<>"Made","",IF(I15="Assist","S","N")) -> N | S14: {=IFERROR(_xlfn.IFS(I14="Offensive Rebound",1),"")} | T14: {=IFERROR(_xlfn.IFS(I14="Defensive Rebound",1),"")} | U14: {=IFERROR(_xlfn.IFS(I14="Assist",1),"")} | V14: {=IFERROR(_xlfn.IFS(I14="Turnover",1),"")} | W14: {=IFERROR(_xlfn.IFS(I14="Steal",1),"")} | X14: {=IFERROR(_xlfn.IFS(I14="Block",1),"")} | Y14: {=IFERROR(_xlfn.IFS(I14="Block Received",1),"")} | Z14: {=IFERROR(_xlfn.IFS(I14="Foul",1,I14="Foul Technical",1,I14="Offensive Foul",1),"")} | AA14: {=IFERROR(_xlfn.IFS(I14="Foul Received",1),"")} | AB14: {=IFERROR(_xlfn.IFS(I14="Starting lineup",C14,I14="Substitution - In",C14),"")} | AC14: {=IFERROR(_xlfn.IFS(I14="Finishing lineup",C14,I14="Substitution - Out",C14),"")} | AD14: {=IF(AC14<>"",LOOKUP(2,1/((G$2:G13=G14)*(AB$2:AB13<>"")),AB$2:AB13)-AC14,"")} | AE14: {=IF(AC14<>"",LOOKUP(2,1/((G$2:G13=G14)*(AB$2:AB13<>"")),AB$2:AB13)-AC14,"")}
A15: 1 | B15: 14 | C15: 0.0064351852 | D15: =MINUTE(C15) -> 9 | E15: =SECOND(C15) -> 16 | F15: LLEIDA | G15: JL12 | H15: =_xlfn.XLOOKUP(G15,'1-Players'!$A$2:$A$27,'1-Players'!$D$2:$D$27,"") -> Atoumane Diagne | I15: 2-Point Shot | J15: Made | K15: {=IFERROR(_xlfn.IFS(I15="Free Throw",1,I15="2-Point Shot",2,I15="Dunk",2,I15="3-Point Shot",3),"")} -> 2 | L15: {=IFERROR(_xlfn.IFS(J15="Made",1,J15="Missed",0),"")} -> 1 | M15: =IFERROR(K15*L15,"") -> 2 | N15: Lay-up | O15: PI | P15: 6 | Q15: S | R15: =IF(J15<>"Made","",IF(I16="Assist","S","N")) -> S | S15: {=IFERROR(_xlfn.IFS(I15="Offensive Rebound",1),"")} | T15: {=IFERROR(_xlfn.IFS(I15="Defensive Rebound",1),"")} | U15: {=IFERROR(_xlfn.IFS(I15="Assist",1),"")} | V15: {=IFERROR(_xlfn.IFS(I15="Turnover",1),"")} | W15: {=IFERROR(_xlfn.IFS(I15="Steal",1),"")} | X15: {=IFERROR(_xlfn.IFS(I15="Block",1),"")} | Y15: {=IFERROR(_xlfn.IFS(I15="Block Received",1),"")} | Z15: {=IFERROR(_xlfn.IFS(I15="Foul",1,I15="Foul Technical",1,I15="Offensive Foul",1),"")} | AA15: {=IFERROR(_xlfn.IFS(I15="Foul Received",1),"")} | AB15: {=IFERROR(_xlfn.IFS(I15="Starting lineup",C15,I15="Substitution - In",C15),"")} | AC15: {=IFERROR(_xlfn.IFS(I15="Finishing lineup",C15,I15="Substitution - Out",C15),"")} | AD15: {=IF(AC15<>"",LOOKUP(2,1/((G$2:G14=G15)*(AB$2:AB14<>"")),AB$2:AB14)-AC15,"")} | AE15: {=IF(AC15<>"",LOOKUP(2,1/((G$2:G14=G15)*(AB$2:AB14<>"")),AB$2:AB14)-AC15,"")}
A16: 1 | B16: 15 | C16: 0.0064351852 | D16: =MINUTE(C16) -> 9 | E16: =SECOND(C16) -> 16 | F16: LLEIDA | G16: JL01 | H16: =_xlfn.XLOOKUP(G16,'1-Players'!$A$2:$A$27,'1-Players'!$D$2:$D$27,"") -> James Batemon | I16: Assist | K16: {=IFERROR(_xlfn.IFS(I16="Free Throw",1,I16="2-Point Shot",2,I16="Dunk",2,I16="3-Point Shot",3),"")} | L16: {=IFERROR(_xlfn.IFS(J16="Made",1,J16="Missed",0),"")} | M16: =IFERROR(K16*L16,"") | R16: =IF(J16<>"Made","",IF(I17="Assist","S","N")) | S16: {=IFERROR(_xlfn.IFS(I16="Offensive Rebound",1),"")} | T16: {=IFERROR(_xlfn.IFS(I16="Defensive Rebound",1),"")} | U16: {=IFERROR(_xlfn.IFS(I16="Assist",1),"")} -> 1 | V16: {=IFERROR(_xlfn.IFS(I16="Turnover",1),"")} | W16: {=IFERROR(_xlfn.IFS(I16="Steal",1),"")} | X16: {=IFERROR(_xlfn.IFS(I16="Block",1),"")} | Y16: {=IFERROR(_xlfn.IFS(I16="Block Received",1),"")} | Z16: {=IFERROR(_xlfn.IFS(I16="Foul",1,I16="Foul Technical",1,I16="Offensive Foul",1),"")} | AA16: {=IFERROR(_xlfn.IFS(I16="Foul Received",1),"")} | AB16: {=IFERROR(_xlfn.IFS(I16="Starting lineup",C16,I16="Substitution - In",C16),"")} | AC16: {=IFERROR(_xlfn.IFS(I16="Finishing lineup",C16,I16="Substitution - Out",C16),"")} | AD16: {=IF(AC16<>"",LOOKUP(2,1/((G$2:G15=G16)*(AB$2:AB15<>"")),AB$2:AB15)-AC16,"")} | AE16: {=IF(AC16<>"",LOOKUP(2,1/((G$2:G15=G16)*(AB$2:AB15<>"")),AB$2:AB15)-AC16,"")}
A17: 1 | B17: 16 | C17: 0.0063310185 | D17: =MINUTE(C17) -> 9 | E17: =SECOND(C17) -> 7 | F17: MANRESA | G17: JM33 | H17: =_xlfn.XLOOKUP(G17,'1-Players'!$A$2:$A$27,'1-Players'!$D$2:$D$27,"") -> Grant Golden | I17: 2-Point Shot | J17: Made | K17: {=IFERROR(_xlfn.IFS(I17="Free Throw",1,I17="2-Point Shot",2,I17="Dunk",2,I17="3-Point Shot",3),"")} -> 2 | L17: {=IFERROR(_xlfn.IFS(J17="Made",1,J17="Missed",0),"")} -> 1 | M17: =IFERROR(K17*L17,"") -> 2 | N17: Floater | O17: PC | P17: 17 | Q17: S | R17: =IF(J17<>"Made","",IF(I18="Assist","S","N")) -> S | S17: {=IFERROR(_xlfn.IFS(I17="Offensive Rebound",1),"")} | T17: {=IFERROR(_xlfn.IFS(I17="Defensive Rebound",1),"")} | U17: {=IFERROR(_xlfn.IFS(I17="Assist",1),"")} | V17: {=IFERROR(_xlfn.IFS(I17="Turnover",1),"")} | W17: {=IFERROR(_xlfn.IFS(I17="Steal",1),"")} | X17: {=IFERROR(_xlfn.IFS(I17="Block",1),"")} | Y17: {=IFERROR(_xlfn.IFS(I17="Block Received",1),"")} | Z17: {=IFERROR(_xlfn.IFS(I17="Foul",1,I17="Foul Technical",1,I17="Offensive Foul",1),"")} | AA17: {=IFERROR(_xlfn.IFS(I17="Foul Received",1),"")} | AB17: {=IFERROR(_xlfn.IFS(I17="Starting lineup",C17,I17="Substitution - In",C17),"")} | AC17: {=IFERROR(_xlfn.IFS(I17="Finishing lineup",C17,I17="Substitution - Out",C17),"")} | AD17: {=IF(AC17<>"",LOOKUP(2,1/((G$2:G16=G17)*(AB$2:AB16<>"")),AB$2:AB16)-AC17,"")} | AE17: {=IF(AC17<>"",LOOKUP(2,1/((G$2:G16=G17)*(AB$2:AB16<>"")),AB$2:AB16)-AC17,"")}
A18: 1 | B18: 17 | C18: 0.0063310185 | D18: =MINUTE(C18) -> 9 | E18: =SECOND(C18) -> 7 | F18: MANRESA | G18: JM02 | H18: =_xlfn.XLOOKUP(G18,'1-Players'!$A$2:$A$27,'1-Players'!$D$2:$D$27,"") -> Hugo Benítez | I18: Assist | K18: {=IFERROR(_xlfn.IFS(I18="Free Throw",1,I18="2-Point Shot",2,I18="Dunk",2,I18="3-Point Shot",3),"")} | L18: {=IFERROR(_xlfn.IFS(J18="Made",1,J18="Missed",0),"")} | M18: =IFERROR(K18*L18,"") | R18: =IF(J18<>"Made","",IF(I19="Assist","S","N")) | S18: {=IFERROR(_xlfn.IFS(I18="Offensive Rebound",1),"")} | T18: {=IFERROR(_xlfn.IFS(I18="Defensive Rebound",1),"")} | U18: {=IFERROR(_xlfn.IFS(I18="Assist",1),"")} -> 1 | V18: {=IFERROR(_xlfn.IFS(I18="Turnover",1),"")} | W18: {=IFERROR(_xlfn.IFS(I18="Steal",1),"")} | X18: {=IFERROR(_xlfn.IFS(I18="Block",1),"")} | Y18: {=IFERROR(_xlfn.IFS(I18="Block Received",1),"")} | Z18: {=IFERROR(_xlfn.IFS(I18="Foul",1,I18="Foul Technical",1,I18="Offensive Foul",1),"")} | AA18: {=IFERROR(_xlfn.IFS(I18="Foul Received",1),"")} | AB18: {=IFERROR(_xlfn.IFS(I18="Starting lineup",C18,I18="Substitution - In",C18),"")} | AC18: {=IFERROR(_xlfn.IFS(I18="Finishing lineup",C18,I18="Substitution - Out",C18),"")} | AD18: {=IF(AC18<>"",LOOKUP(2,1/((G$2:G17=G18)*(AB$2:AB17<>"")),AB$2:AB17)-AC18,"")} | AE18: {=IF(AC18<>"",LOOKUP(2,1/((G$2:G17=G18)*(AB$2:AB17<>"")),AB$2:AB17)-AC18,"")}
A19: 1 | B19: 18 | C19: 0.0061458333 | D19: =MINUTE(C19) -> 8 | E19: =SECOND(C19) -> 51 | F19: LLEIDA | G19: JL12 | H19: =_xlfn.XLOOKUP(G19,'1-Players'!$A$2:$A$27,'1-Players'!$D$2:$D$27,"") -> Atoumane Diagne | I19: Dunk | J19: Made | K19: {=IFERROR(_xlfn.IFS(I19="Free Throw",1,I19="2-Point Shot",2,I19="Dunk",2,I19="3-Point Shot",3),"")} -> 2 | L19: {=IFERROR(_xlfn.IFS(J19="Made",1,J19="Missed",0),"")} -> 1 | M19: =IFERROR(K19*L19,"") -> 2 | N19: Dunk | O19: PD | P19: 16 | Q19: N | R19: =IF(J19<>"Made","",IF(I20="Assist","S","N")) -> S | S19: {=IFERROR(_xlfn.IFS(I19="Offensive Rebound",1),"")} | T19: {=IFERROR(_xlfn.IFS(I19="Defensive Rebound",1),"")} | U19: {=IFERROR(_xlfn.IFS(I19="Assist",1),"")} | V19: {=IFERROR(_xlfn.IFS(I19="Turnover",1),"")} | W19: {=IFERROR(_xlfn.IFS(I19="Steal",1),"")} | X19: {=IFERROR(_xlfn.IFS(I19="Block",1),"")} | Y19: {=IFERROR(_xlfn.IFS(I19="Block Received",1),"")} | Z19: {=IFERROR(_xlfn.IFS(I19="Foul",1,I19="Foul Technical",1,I19="Offensive Foul",1),"")} | AA19: {=IFERROR(_xlfn.IFS(I19="Foul Received",1),"")} | AB19: {=IFERROR(_xlfn.IFS(I19="Starting lineup",C19,I19="Substitution - In",C19),"")} | AC19: {=IFERROR(_xlfn.IFS(I19="Finishing lineup",C19,I19="Substitution - Out",C19),"")} | AD19: {=IF(AC19<>"",LOOKUP(2,1/((G$2:G18=G19)*(AB$2:AB18<>"")),AB$2:AB18)-AC19,"")} | AE19: {=IF(AC19<>"",LOOKUP(2,1/((G$2:G18=G19)*(AB$2:AB18<>"")),AB$2:AB18)-AC19,"")}
A20: 1 | B20: 19 | C20: 0.0061458333 | D20: =MINUTE(C20) -> 8 | E20: =SECOND(C20) -> 51 | F20: LLEIDA | G20: JL04 | H20: =_xlfn.XLOOKUP(G20,'1-Players'!$A$2:$A$27,'1-Players'!$D$2:$D$27,"") -> Caleb Agada | I20: Assist | K20: {=IFERROR(_xlfn.IFS(I20="Free Throw",1,I20="2-Point Shot",2,I20="Dunk",2,I20="3-Point Shot",3),"")} | L20: {=IFERROR(_xlfn.IFS(J20="Made",1,J20="Missed",0),"")} | M20: =IFERROR(K20*L20,"") | R20: =IF(J20<>"Made","",IF(I21="Assist","S","N")) | S20: {=IFERROR(_xlfn.IFS(I20="Offensive Rebound",1),"")} | T20: {=IFERROR(_xlfn.IFS(I20="Defensive Rebound",1),"")} | U20: {=IFERROR(_xlfn.IFS(I20="Assist",1),"")} -> 1 | V20: {=IFERROR(_xlfn.IFS(I20="Turnover",1),"")} | W20: {=IFERROR(_xlfn.IFS(I20="Steal",1),"")} | X20: {=IFERROR(_xlfn.IFS(I20="Block",1),"")} | Y20: {=IFERROR(_xlfn.IFS(I20="Block Received",1),"")} | Z20: {=IFERROR(_xlfn.IFS(I20="Foul",1,I20="Foul Technical",1,I20="Offensive Foul",1),"")} | AA20: {=IFERROR(_xlfn.IFS(I20="Foul Received",1),"")} | AB20: {=IFERROR(_xlfn.IFS(I20="Starting lineup",C20,I20="Substitution - In",C20),"")} | AC20: {=IFERROR(_xlfn.IFS(I20="Finishing lineup",C20,I20="Substitution - Out",C20),"")} | AD20: {=IF(AC20<>"",LOOKUP(2,1/((G$2:G19=G20)*(AB$2:AB19<>"")),AB$2:AB19)-AC20,"")} | AE20: {=IF(AC20<>"",LOOKUP(2,1/((G$2:G19=G20)*(AB$2:AB19<>"")),AB$2:AB19)-AC20,"")}
A21: 1 | B21: 20 | C21: 0.0059143519 | D21: =MINUTE(C21) -> 8 | E21: =SECOND(C21) -> 31 | F21: MANRESA | G21: JM02 | H21: =_xlfn.XLOOKUP(G21,'1-Players'!$A$2:$A$27,'1-Players'!$D$2:$D$27,"") -> Hugo Benítez | I21: 3-Point Shot | J21: Made | K21: {=IFERROR(_xlfn.IFS(I21="Free Throw",1,I21="2-Point Shot",2,I21="Dunk",2,I21="3-Point Shot",3),"")} -> 3 | L21: {=IFERROR(_xlfn.IFS(J21="Made",1,J21="Missed",0),"")} -> 1 | M21: =IFERROR(K21*L21,"") -> 3 | N21: Spot-up | O21: TI | P21: 9 | Q21: N | R21: =IF(J21<>"Made","",IF(I22="Assist","S","N")) -> S | S21: {=IFERROR(_xlfn.IFS(I21="Offensive Rebound",1),"")} | T21: {=IFERROR(_xlfn.IFS(I21="Defensive Rebound",1),"")} | U21: {=IFERROR(_xlfn.IFS(I21="Assist",1),"")} | V21: {=IFERROR(_xlfn.IFS(I21="Turnover",1),"")} | W21: {=IFERROR(_xlfn.IFS(I21="Steal",1),"")} | X21: {=IFERROR(_xlfn.IFS(I21="Block",1),"")} | Y21: {=IFERROR(_xlfn.IFS(I21="Block Received",1),"")} | Z21: {=IFERROR(_xlfn.IFS(I21="Foul",1,I21="Foul Technical",1,I21="Offensive Foul",1),"")} | AA21: {=IFERROR(_xlfn.IFS(I21="Foul Received",1),"")} | AB21: {=IFERROR(_xlfn.IFS(I21="Starting lineup",C21,I21="Substitution - In",C21),"")} | AC21: {=IFERROR(_xlfn.IFS(I21="Finishing lineup",C21,I21="Substitution - Out",C21),"")} | AD21: {=IF(AC21<>"",LOOKUP(2,1/((G$2:G20=G21)*(AB$2:AB20<>"")),AB$2:AB20)-AC21,"")} | AE21: {=IF(AC21<>"",LOOKUP(2,1/((G$2:G20=G21)*(AB$2:AB20<>"")),AB$2:AB20)-AC21,"")}
A22: 1 | B22: 21 | C22: 0.0061458333 | D22: =MINUTE(C22) -> 8 | E22: =SECOND(C22) -> 51 | F22: MANRESA | G22: JM32 | H22: =_xlfn.XLOOKUP(G22,'1-Players'!$A$2:$A$27,'1-Players'!$D$2:$D$27,"") -> Retin Obasohan | I22: Assist | K22: {=IFERROR(_xlfn.IFS(I22="Free Throw",1,I22="2-Point Shot",2,I22="Dunk",2,I22="3-Point Shot",3),"")} | L22: {=IFERROR(_xlfn.IFS(J22="Made",1,J22="Missed",0),"")} | M22: =IFERROR(K22*L22,"") | R22: =IF(J22<>"Made","",IF(I23="Assist","S","N")) | S22: {=IFERROR(_xlfn.IFS(I22="Offensive Rebound",1),"")} | T22: {=IFERROR(_xlfn.IFS(I22="Defensive Rebound",1),"")} | U22: {=IFERROR(_xlfn.IFS(I22="Assist",1),"")} -> 1 | V22: {=IFERROR(_xlfn.IFS(I22="Turnover",1),"")} | W22: {=IFERROR(_xlfn.IFS(I22="Steal",1),"")} | X22: {=IFERROR(_xlfn.IFS(I22="Block",1),"")} | Y22: {=IFERROR(_xlfn.IFS(I22="Block Received",1),"")} | Z22: {=IFERROR(_xlfn.IFS(I22="Foul",1,I22="Foul Technical",1,I22="Offensive Foul",1),"")} | AA22: {=IFERROR(_xlfn.IFS(I22="Foul Received",1),"")} | AB22: {=IFERROR(_xlfn.IFS(I22="Starting lineup",C22,I22="Substitution - In",C22),"")} | AC22: {=IFERROR(_xlfn.IFS(I22="Finishing lineup",C22,I22="Substitution - Out",C22),"")} | AD22: {=IF(AC22<>"",LOOKUP(2,1/((G$2:G21=G22)*(AB$2:AB21<>"")),AB$2:AB21)-AC22,"")} | AE22: {=IF(AC22<>"",LOOKUP(2,1/((G$2:G21=G22)*(AB$2:AB21<>"")),AB$2:AB21)-AC22,"")}
A23: 1 | B23: 22 | C23: 0.005625 | D23: =MINUTE(C23) -> 8 | E23: =SECOND(C23) -> 6 | F23: LLEIDA | G23: JL01 | H23: =_xlfn.XLOOKUP(G23,'1-Players'!$A$2:$A$27,'1-Players'!$D$2:$D$27,"") -> James Batemon | I23: 2-Point Shot | J23: Missed | K23: {=IFERROR(_xlfn.IFS(I23="Free Throw",1,I23="2-Point Shot",2,I23="Dunk",2,I23="3-Point Shot",3),"")} -> 2 | L23: {=IFERROR(_xlfn.IFS(J23="Made",1,J23="Missed",0),"")} -> 0 | M23: =IFERROR(K23*L23,"") -> 0 | N23: Lay-up | O23: PI | P23: 5 | Q23: S | R23: =IF(J23<>"Made","",IF(I24="Assist","S","N")) | S23: {=IFERROR(_xlfn.IFS(I23="Offensive Rebound",1),"")} | T23: {=IFERROR(_xlfn.IFS(I23="Defensive Rebound",1),"")} | U23: {=IFERROR(_xlfn.IFS(I23="Assist",1),"")} | V23: {=IFERROR(_xlfn.IFS(I23="Turnover",1),"")} | W23: {=IFERROR(_xlfn.IFS(I23="Steal",1),"")} | X23: {=IFERROR(_xlfn.IFS(I23="Block",1),"")} | Y23: {=IFERROR(_xlfn.IFS(I23="Block Received",1),"")} | Z23: {=IFERROR(_xlfn.IFS(I23="Foul",1,I23="Foul Technical",1,I23="Offensive Foul",1),"")} | AA23: {=IFERROR(_xlfn.IFS(I23="Foul Received",1),"")} | AB23: {=IFERROR(_xlfn.IFS(I23="Starting lineup",C23,I23="Substitution - In",C23),"")} | AC23: {=IFERROR(_xlfn.IFS(I23="Finishing lineup",C23,I23="Substitution - Out",C23),"")} | AD23: {=IF(AC23<>"",LOOKUP(2,1/((G$2:G22=G23)*(AB$2:AB22<>"")),AB$2:AB22)-AC23,"")} | AE23: {=IF(AC23<>"",LOOKUP(2,1/((G$2:G22=G23)*(AB$2:AB22<>"")),AB$2:AB22)-AC23,"")}
A24: 1 | B24: 23 | C24: 0.005625 | D24: =MINUTE(C24) -> 8 | E24: =SECOND(C24) -> 6 | F24: MANRESA | G24: JM08 | H24: =_xlfn.XLOOKUP(G24,'1-Players'!$A$2:$A$27,'1-Players'!$D$2:$D$27,"") -> Álex Reyes | I24: Defensive Rebound | K24: {=IFERROR(_xlfn.IFS(I24="Free Throw",1,I24="2-Point Shot",2,I24="Dunk",2,I24="3-Point Shot",3),"")} | L24: {=IFERROR(_xlfn.IFS(J24="Made",1,J24="Missed",0),"")} | M24: =IFERROR(K24*L24,"") | R24: =IF(J24<>"Made","",IF(I25="Assist","S","N")) | S24: {=IFERROR(_xlfn.IFS(I24="Offensive Rebound",1),"")} | T24: {=IFERROR(_xlfn.IFS(I24="Defensive Rebound",1),"")} -> 1 | U24: {=IFERROR(_xlfn.IFS(I24="Assist",1),"")} | V24: {=IFERROR(_xlfn.IFS(I24="Turnover",1),"")} | W24: {=IFERROR(_xlfn.IFS(I24="Steal",1),"")} | X24: {=IFERROR(_xlfn.IFS(I24="Block",1),"")} | Y24: {=IFERROR(_xlfn.IFS(I24="Block Received",1),"")} | Z24: {=IFERROR(_xlfn.IFS(I24="Foul",1,I24="Foul Technical",1,I24="Offensive Foul",1),"")} | AA24: {=IFERROR(_xlfn.IFS(I24="Foul Received",1),"")} | AB24: {=IFERROR(_xlfn.IFS(I24="Starting lineup",C24,I24="Substitution - In",C24),"")} | AC24: {=IFERROR(_xlfn.IFS(I24="Finishing lineup",C24,I24="Substitution - Out",C24),"")} | AD24: {=IF(AC24<>"",LOOKUP(2,1/((G$2:G23=G24)*(AB$2:AB23<>"")),AB$2:AB23)-AC24,"")} | AE24: {=IF(AC24<>"",LOOKUP(2,1/((G$2:G23=G24)*(AB$2:AB23<>"")),AB$2:AB23)-AC24,"")}
A25: 1 | B25: 24 | C25: 0.0055208333 | D25: =MINUTE(C25) -> 7 | E25: =SECOND(C25) -> 57 | F25: MANRESA | G25: JM08 | H25: =_xlfn.XLOOKUP(G25,'1-Players'!$A$2:$A$27,'1-Players'!$D$2:$D$27,"") -> Álex Reyes | I25: 3-Point Shot | J25: Made | K25: {=IFERROR(_xlfn.IFS(I25="Free Throw",1,I25="2-Point Shot",2,I25="Dunk",2,I25="3-Point Shot",3),"")} -> 3 | L25: {=IFERROR(_xlfn.IFS(J25="Made",1,J25="Missed",0),"")} -> 1 | M25: =IFERROR(K25*L25,"") -> 3 | N25: Catch&Shoot | O25: TD | P25: 16 | Q25: S | R25: =IF(J25<>"Made","",IF(I26="Assist","S","N")) -> S | S25: {=IFERROR(_xlfn.IFS(I25="Offensive Rebound",1),"")} | T25: {=IFERROR(_xlfn.IFS(I25="Defensive Rebound",1),"")} | U25: {=IFERROR(_xlfn.IFS(I25="Assist",1),"")} | V25: {=IFERROR(_xlfn.IFS(I25="Turnover",1),"")} | W25: {=IFERROR(_xlfn.IFS(I25="Steal",1),"")} | X25: {=IFERROR(_xlfn.IFS(I25="Block",1),"")} | Y25: {=IFERROR(_xlfn.IFS(I25="Block Received",1),"")} | Z25: {=IFERROR(_xlfn.IFS(I25="Foul",1,I25="Foul Technical",1,I25="Offensive Foul",1),"")} | AA25: {=IFERROR(_xlfn.IFS(I25="Foul Received",1),"")} | AB25: {=IFERROR(_xlfn.IFS(I25="Starting lineup",C25,I25="Substitution - In",C25),"")} | AC25: {=IFERROR(_xlfn.IFS(I25="Finishing lineup",C25,I25="Substitution - Out",C25),"")} | AD25: {=IF(AC25<>"",LOOKUP(2,1/((G$2:G24=G25)*(AB$2:AB24<>"")),AB$2:AB24)-AC25,"")} | AE25: {=IF(AC25<>"",LOOKUP(2,1/((G$2:G24=G25)*(AB$2:AB24<>"")),AB$2:AB24)-AC25,"")}
A26: 1 | B26: 25 | C26: 0.0055208333 | D26: =MINUTE(C26) -> 7 | E26: =SECOND(C26) -> 57 | F26: MANRESA | G26: JM33 | H26: =_xlfn.XLOOKUP(G26,'1-Players'!$A$2:$A$27,'1-Players'!$D$2:$D$27,"") -> Grant Golden | I26: Assist | K26: {=IFERROR(_xlfn.IFS(I26="Free Throw",1,I26="2-Point Shot",2,I26="Dunk",2,I26="3-Point Shot",3),"")} | L26: {=IFERROR(_xlfn.IFS(J26="Made",1,J26="Missed",0),"")} | M26: =IFERROR(K26*L26,"") | R26: =IF(J26<>"Made","",IF(I27="Assist","S","N")) | S26: {=IFERROR(_xlfn.IFS(I26="Offensive Rebound",1),"")} | T26: {=IFERROR(_xlfn.IFS(I26="Defensive Rebound",1),"")} | U26: {=IFERROR(_xlfn.IFS(I26="Assist",1),"")} -> 1 | V26: {=IFERROR(_xlfn.IFS(I26="Turnover",1),"")} | W26: {=IFERROR(_xlfn.IFS(I26="Steal",1),"")} | X26: {=IFERROR(_xlfn.IFS(I26="Block",1),"")} | Y26: {=IFERROR(_xlfn.IFS(I26="Block Received",1),"")} | Z26: {=IFERROR(_xlfn.IFS(I26="Foul",1,I26="Foul Technical",1,I26="Offensive Foul",1),"")} | AA26: {=IFERROR(_xlfn.IFS(I26="Foul Received",1),"")} | AB26: {=IFERROR(_xlfn.IFS(I26="Starting lineup",C26,I26="Substitution - In",C26),"")} | AC26: {=IFERROR(_xlfn.IFS(I26="Finishing lineup",C26,I26="Substitution - Out",C26),"")} | AD26: {=IF(AC26<>"",LOOKUP(2,1/((G$2:G25=G26)*(AB$2:AB25<>"")),AB$2:AB25)-AC26,"")} | AE26: {=IF(AC26<>"",LOOKUP(2,1/((G$2:G25=G26)*(AB$2:AB25<>"")),AB$2:AB25)-AC26,"")}
A27: 1 | B27: 26 | C27: 0.0052662037 | D27: =MINUTE(C27) -> 7 | E27: =SECOND(C27) -> 35 | F27: MANRESA | G27: JM02 | H27: =_xlfn.XLOOKUP(G27,'1-Players'!$A$2:$A$27,'1-Players'!$D$2:$D$27,"") -> Hugo Benítez | I27: Foul | J27: 2FT | K27: {=IFERROR(_xlfn.IFS(I27="Free Throw",1,I27="2-Point Shot",2,I27="Dunk",2,I27="3-Point Shot",3),"")} | L27: {=IFERROR(_xlfn.IFS(J27="Made",1,J27="Missed",0),"")} | M27: =IFERROR(K27*L27,"") | R27: =IF(J27<>"Made","",IF(I28="Assist","S","N")) | S27: {=IFERROR(_xlfn.IFS(I27="Offensive Rebound",1),"")} | T27: {=IFERROR(_xlfn.IFS(I27="Defensive Rebound",1),"")} | U27: {=IFERROR(_xlfn.IFS(I27="Assist",1),"")} | V27: {=IFERROR(_xlfn.IFS(I27="Turnover",1),"")} | W27: {=IFERROR(_xlfn.IFS(I27="Steal",1),"")} | X27: {=IFERROR(_xlfn.IFS(I27="Block",1),"")} | Y27: {=IFERROR(_xlfn.IFS(I27="Block Received",1),"")} | Z27: {=IFERROR(_xlfn.IFS(I27="Foul",1,I27="Foul Technical",1,I27="Offensive Foul",1),"")} -> 1 | AA27: {=IFERROR(_xlfn.IFS(I27="Foul Received",1),"")} | AB27: {=IFERROR(_xlfn.IFS(I27="Starting lineup",C27,I27="Substitution - In",C27),"")} | AC27: {=IFERROR(_xlfn.IFS(I27="Finishing lineup",C27,I27="Substitution - Out",C27),"")} | AD27: {=IF(AC27<>"",LOOKUP(2,1/((G$2:G26=G27)*(AB$2:AB26<>"")),AB$2:AB26)-AC27,"")} | AE27: {=IF(AC27<>"",LOOKUP(2,1/((G$2:G26=G27)*(AB$2:AB26<>"")),AB$2:AB26)-AC27,"")}
A28: 1 | B28: 27 | C28: 0.0052662037 | D28: =MINUTE(C28) -> 7 | E28: =SECOND(C28) -> 35 | F28: LLEIDA | G28: JL04 | H28: =_xlfn.XLOOKUP(G28,'1-Players'!$A$2:$A$27,'1-Players'!$D$2:$D$27,"") -> Caleb Agada | I28: Foul Received | K28: {=IFERROR(_xlfn.IFS(I28="Free Throw",1,I28="2-Point Shot",2,I28="Dunk",2,I28="3-Point Shot",3),"")} | L28: {=IFERROR(_xlfn.IFS(J28="Made",1,J28="Missed",0),"")} | M28: =IFERROR(K28*L28,"") | R28: =IF(J28<>"Made","",IF(I29="Assist","S","N")) | S28: {=IFERROR(_xlfn.IFS(I28="Offensive Rebound",1),"")} | T28: {=IFERROR(_xlfn.IFS(I28="Defensive Rebound",1),"")} | U28: {=IFERROR(_xlfn.IFS(I28="Assist",1),"")} | V28: {=IFERROR(_xlfn.IFS(I28="Turnover",1),"")} | W28: {=IFERROR(_xlfn.IFS(I28="Steal",1),"")} | X28: {=IFERROR(_xlfn.IFS(I28="Block",1),"")} | Y28: {=IFERROR(_xlfn.IFS(I28="Block Received",1),"")} | Z28: {=IFERROR(_xlfn.IFS(I28="Foul",1,I28="Foul Technical",1,I28="Offensive Foul",1),"")} | AA28: {=IFERROR(_xlfn.IFS(I28="Foul Received",1),"")} -> 1 | AB28: {=IFERROR(_xlfn.IFS(I28="Starting lineup",C28,I28="Substitution - In",C28),"")} | AC28: {=IFERROR(_xlfn.IFS(I28="Finishing lineup",C28,I28="Substitution - Out",C28),"")} | AD28: {=IF(AC28<>"",LOOKUP(2,1/((G$2:G27=G28)*(AB$2:AB27<>"")),AB$2:AB27)-AC28,"")} | AE28: {=IF(AC28<>"",LOOKUP(2,1/((G$2:G27=G28)*(AB$2:AB27<>"")),AB$2:AB27)-AC28,"")}
A29: 1 | B29: 28 | C29: 0.0052662037 | D29: =MINUTE(C29) -> 7 | E29: =SECOND(C29) -> 35 | F29: LLEIDA | G29: JL04 | H29: =_xlfn.XLOOKUP(G29,'1-Players'!$A$2:$A$27,'1-Players'!$D$2:$D$27,"") -> Caleb Agada | I29: Free Throw | J29: Made | K29: {=IFERROR(_xlfn.IFS(I29="Free Throw",1,I29="2-Point Shot",2,I29="Dunk",2,I29="3-Point Shot",3),"")} -> 1 | L29: {=IFERROR(_xlfn.IFS(J29="Made",1,J29="Missed",0),"")} -> 1 | M29: =IFERROR(K29*L29,"") -> 1 | R29: =IF(J29<>"Made","",IF(I30="Assist","S","N")) -> N | S29: {=IFERROR(_xlfn.IFS(I29="Offensive Rebound",1),"")} | T29: {=IFERROR(_xlfn.IFS(I29="Defensive Rebound",1),"")} | U29: {=IFERROR(_xlfn.IFS(I29="Assist",1),"")} | V29: {=IFERROR(_xlfn.IFS(I29="Turnover",1),"")} | W29: {=IFERROR(_xlfn.IFS(I29="Steal",1),"")} | X29: {=IFERROR(_xlfn.IFS(I29="Block",1),"")} | Y29: {=IFERROR(_xlfn.IFS(I29="Block Received",1),"")} | Z29: {=IFERROR(_xlfn.IFS(I29="Foul",1,I29="Foul Technical",1,I29="Offensive Foul",1),"")} | AA29: {=IFERROR(_xlfn.IFS(I29="Foul Received",1),"")} | AB29: {=IFERROR(_xlfn.IFS(I29="Starting lineup",C29,I29="Substitution - In",C29),"")} | AC29: {=IFERROR(_xlfn.IFS(I29="Finishing lineup",C29,I29="Substitution - Out",C29),"")} | AD29: {=IF(AC29<>"",LOOKUP(2,1/((G$2:G28=G29)*(AB$2:AB28<>"")),AB$2:AB28)-AC29,"")} | AE29: {=IF(AC29<>"",LOOKUP(2,1/((G$2:G28=G29)*(AB$2:AB28<>"")),AB$2:AB28)-AC29,"")}
A30: 1 | B30: 29 | C30: 0.0052662037 | D30: =MINUTE(C30) -> 7 | E30: =SECOND(C30) -> 35 | F30: LLEIDA | G30: JL04 | H30: =_xlfn.XLOOKUP(G30,'1-Players'!$A$2:$A$27,'1-Players'!$D$2:$D$27,"") -> Caleb Agada | I30: Free Throw | J30: Made | K30: {=IFERROR(_xlfn.IFS(I30="Free Throw",1,I30="2-Point Shot",2,I30="Dunk",2,I30="3-Point Shot",3),"")} -> 1 | L30: {=IFERROR(_xlfn.IFS(J30="Made",1,J30="Missed",0),"")} -> 1 | M30: =IFERROR(K30*L30,"") -> 1 | R30: =IF(J30<>"Made","",IF(I31="Assist","S","N")) -> N | S30: {=IFERROR(_xlfn.IFS(I30="Offensive Rebound",1),"")} | T30: {=IFERROR(_xlfn.IFS(I30="Defensive Rebound",1),"")} | U30: {=IFERROR(_xlfn.IFS(I30="Assist",1),"")} | V30: {=IFERROR(_xlfn.IFS(I30="Turnover",1),"")} | W30: {=IFERROR(_xlfn.IFS(I30="Steal",1),"")} | X30: {=IFERROR(_xlfn.IFS(I30="Block",1),"")} | Y30: {=IFERROR(_xlfn.IFS(I30="Block Received",1),"")} | Z30: {=IFERROR(_xlfn.IFS(I30="Foul",1,I30="Foul Technical",1,I30="Offensive Foul",1),"")} | AA30: {=IFERROR(_xlfn.IFS(I30="Foul Received",1),"")} | AB30: {=IFERROR(_xlfn.IFS(I30="Starting lineup",C30,I30="Substitution - In",C30),"")} | AC30: {=IFERROR(_xlfn.IFS(I30="Finishing lineup",C30,I30="Substitution - Out",C30),"")} | AD30: {=IF(AC30<>"",LOOKUP(2,1/((G$2:G29=G30)*(AB$2:AB29<>"")),AB$2:AB29)-AC30,"")} | AE30: {=IF(AC30<>"",LOOKUP(2,1/((G$2:G29=G30)*(AB$2:AB29<>"")),AB$2:AB29)-AC30,"")}
A31: 1 | B31: 30 | C31: 0.0052199074 | D31: =MINUTE(C31) -> 7 | E31: =SECOND(C31) -> 31 | F31: MANRESA | G31: JM12 | H31: =_xlfn.XLOOKUP(G31,'1-Players'!$A$2:$A$27,'1-Players'!$D$2:$D$27,"") -> Marcis Steinbergs | I31: 2-Point Shot | J31: Missed | K31: {=IFERROR(_xlfn.IFS(I31="Free Throw",1,I31="2-Point Shot",2,I31="Dunk",2,I31="3-Point Shot",3),"")} -> 2 | L31: {=IFERROR(_xlfn.IFS(J31="Made",1,J31="Missed",0),"")} -> 0 | M31: =IFERROR(K31*L31,"") -> 0 | N31: Floater | O31: MD | P31: 6 | Q31: S | R31: =IF(J31<>"Made","",IF(I32="Assist","S","N")) | S31: {=IFERROR(_xlfn.IFS(I31="Offensive Rebound",1),"")} | T31: {=IFERROR(_xlfn.IFS(I31="Defensive Rebound",1),"")} | U31: {=IFERROR(_xlfn.IFS(I31="Assist",1),"")} | V31: {=IFERROR(_xlfn.IFS(I31="Turnover",1),"")} | W31: {=IFERROR(_xlfn.IFS(I31="Steal",1),"")} | X31: {=IFERROR(_xlfn.IFS(I31="Block",1),"")} | Y31: {=IFERROR(_xlfn.IFS(I31="Block Received",1),"")} | Z31: {=IFERROR(_xlfn.IFS(I31="Foul",1,I31="Foul Technical",1,I31="Offensive Foul",1),"")} | AA31: {=IFERROR(_xlfn.IFS(I31="Foul Received",1),"")} | AB31: {=IFERROR(_xlfn.IFS(I31="Starting lineup",C31,I31="Substitution - In",C31),"")} | AC31: {=IFERROR(_xlfn.IFS(I31="Finishing lineup",C31,I31="Substitution - Out",C31),"")} | AD31: {=IF(AC31<>"",LOOKUP(2,1/((G$2:G30=G31)*(AB$2:AB30<>"")),AB$2:AB30)-AC31,"")} | AE31: {=IF(AC31<>"",LOOKUP(2,1/((G$2:G30=G31)*(AB$2:AB30<>"")),AB$2:AB30)-AC31,"")}
A32: 1 | B32: 31 | C32: 0.0052199074 | D32: =MINUTE(C32) -> 7 | E32: =SECOND(C32) -> 31 | F32: MANRESA | G32: JM12 | H32: =_xlfn.XLOOKUP(G32,'1-Players'!$A$2:$A$27,'1-Players'!$D$2:$D$27,"") -> Marcis Steinbergs | I32: Block Received | K32: {=IFERROR(_xlfn.IFS(I32="Free Throw",1,I32="2-Point Shot",2,I32="Dunk",2,I32="3-Point Shot",3),"")} | L32: {=IFERROR(_xlfn.IFS(J32="Made",1,J32="Missed",0),"")} | M32: =IFERROR(K32*L32,"") | R32: =IF(J32<>"Made","",IF(I33="Assist","S","N")) | S32: {=IFERROR(_xlfn.IFS(I32="Offensive Rebound",1),"")} | T32: {=IFERROR(_xlfn.IFS(I32="Defensive Rebound",1),"")} | U32: {=IFERROR(_xlfn.IFS(I32="Assist",1),"")} | V32: {=IFERROR(_xlfn.IFS(I32="Turnover",1),"")} | W32: {=IFERROR(_xlfn.IFS(I32="Steal",1),"")} | X32: {=IFERROR(_xlfn.IFS(I32="Block",1),"")} | Y32: {=IFERROR(_xlfn.IFS(I32="Block Received",1),"")} -> 1 | Z32: {=IFERROR(_xlfn.IFS(I32="Foul",1,I32="Foul Technical",1,I32="Offensive Foul",1),"")} | AA32: {=IFERROR(_xlfn.IFS(I32="Foul Received",1),"")} | AB32: {=IFERROR(_xlfn.IFS(I32="Starting lineup",C32,I32="Substitution - In",C32),"")} | AC32: {=IFERROR(_xlfn.IFS(I32="Finishing lineup",C32,I32="Substitution - Out",C32),"")} | AD32: {=IF(AC32<>"",LOOKUP(2,1/((G$2:G31=G32)*(AB$2:AB31<>"")),AB$2:AB31)-AC32,"")} | AE32: {=IF(AC32<>"",LOOKUP(2,1/((G$2:G31=G32)*(AB$2:AB31<>"")),AB$2:AB31)-AC32,"")}
A33: 1 | B33: 32 | C33: 0.0052199074 | D33: =MINUTE(C33) -> 7 | E33: =SECOND(C33) -> 31 | F33: LLEIDA | G33: JL14 | H33: =_xlfn.XLOOKUP(G33,'1-Players'!$A$2:$A$27,'1-Players'!$D$2:$D$27,"") -> Mikel Sanz | I33: Block | K33: {=IFERROR(_xlfn.IFS(I33="Free Throw",1,I33="2-Point Shot",2,I33="Dunk",2,I33="3-Point Shot",3),"")} | L33: {=IFERROR(_xlfn.IFS(J33="Made",1,J33="Missed",0),"")} | M33: =IFERROR(K33*L33,"") | R33: =IF(J33<>"Made","",IF(I34="Assist","S","N")) | S33: {=IFERROR(_xlfn.IFS(I33="Offensive Rebound",1),"")} | T33: {=IFERROR(_xlfn.IFS(I33="Defensive Rebound",1),"")} | U33: {=IFERROR(_xlfn.IFS(I33="Assist",1),"")} | V33: {=IFERROR(_xlfn.IFS(I33="Turnover",1),"")} | W33: {=IFERROR(_xlfn.IFS(I33="Steal",1),"")} | X33: {=IFERROR(_xlfn.IFS(I33="Block",1),"")} -> 1 | Y33: {=IFERROR(_xlfn.IFS(I33="Block Received",1),"")} | Z33: {=IFERROR(_xlfn.IFS(I33="Foul",1,I33="Foul Technical",1,I33="Offensive Foul",1),"")} | AA33: {=IFERROR(_xlfn.IFS(I33="Foul Received",1),"")} | AB33: {=IFERROR(_xlfn.IFS(I33="Starting lineup",C33,I33="Substitution - In",C33),"")} | AC33: {=IFERROR(_xlfn.IFS(I33="Finishing lineup",C33,I33="Substitution - Out",C33),"")} | AD33: {=IF(AC33<>"",LOOKUP(2,1/((G$2:G32=G33)*(AB$2:AB32<>"")),AB$2:AB32)-AC33,"")} | AE33: {=IF(AC33<>"",LOOKUP(2,1/((G$2:G32=G33)*(AB$2:AB32<>"")),AB$2:AB32)-AC33,"")}
A34: 1 | B34: 33 | C34: 0.0052199074 | D34: =MINUTE(C34) -> 7 | E34: =SECOND(C34) -> 31 | F34: MANRESA | G34: MAN | H34: =_xlfn.XLOOKUP(G34,'1-Players'!$A$2:$A$27,'1-Players'!$D$2:$D$27,"") -> TEAM - Manresa | I34: Offensive Rebound | K34: {=IFERROR(_xlfn.IFS(I34="Free Throw",1,I34="2-Point Shot",2,I34="Dunk",2,I34="3-Point Shot",3),"")} | L34: {=IFERROR(_xlfn.IFS(J34="Made",1,J34="Missed",0),"")} | M34: =IFERROR(K34*L34,"") | R34: =IF(J34<>"Made","",IF(I35="Assist","S","N")) | S34: {=IFERROR(_xlfn.IFS(I34="Offensive Rebound",1),"")} -> 1 | T34: {=IFERROR(_xlfn.IFS(I34="Defensive Rebound",1),"")} | U34: {=IFERROR(_xlfn.IFS(I34="Assist",1),"")} | V34: {=IFERROR(_xlfn.IFS(I34="Turnover",1),"")} | W34: {=IFERROR(_xlfn.IFS(I34="Steal",1),"")} | X34: {=IFERROR(_xlfn.IFS(I34="Block",1),"")} | Y34: {=IFERROR(_xlfn.IFS(I34="Block Received",1),"")} | Z34: {=IFERROR(_xlfn.IFS(I34="Foul",1,I34="Foul Technical",1,I34="Offensive Foul",1),"")} | AA34: {=IFERROR(_xlfn.IFS(I34="Foul Received",1),"")} | AB34: {=IFERROR(_xlfn.IFS(I34="Starting lineup",C34,I34="Substitution - In",C34),"")} | AC34: {=IFERROR(_xlfn.IFS(I34="Finishing lineup",C34,I34="Substitution - Out",C34),"")} | AD34: {=IF(AC34<>"",LOOKUP(2,1/((G$2:G33=G34)*(AB$2:AB33<>"")),AB$2:AB33)-AC34,"")} | AE34: {=IF(AC34<>"",LOOKUP(2,1/((G$2:G33=G34)*(AB$2:AB33<>"")),AB$2:AB33)-AC34,"")}
A35: 1 | B35: 34 | C35: 0.0052199074 | D35: =MINUTE(C35) -> 7 | E35: =SECOND(C35) -> 31 | F35: LLEIDA | G35: JL12 | H35: =_xlfn.XLOOKUP(G35,'1-Players'!$A$2:$A$27,'1-Players'!$D$2:$D$27,"") -> Atoumane Diagne | I35: Foul | K35: {=IFERROR(_xlfn.IFS(I35="Free Throw",1,I35="2-Point Shot",2,I35="Dunk",2,I35="3-Point Shot",3),"")} | L35: {=IFERROR(_xlfn.IFS(J35="Made",1,J35="Missed",0),"")} | M35: =IFERROR(K35*L35,"") | R35: =IF(J35<>"Made","",IF(I36="Assist","S","N")) | S35: {=IFERROR(_xlfn.IFS(I35="Offensive Rebound",1),"")} | T35: {=IFERROR(_xlfn.IFS(I35="Defensive Rebound",1),"")} | U35: {=IFERROR(_xlfn.IFS(I35="Assist",1),"")} | V35: {=IFERROR(_xlfn.IFS(I35="Turnover",1),"")} | W35: {=IFERROR(_xlfn.IFS(I35="Steal",1),"")} | X35: {=IFERROR(_xlfn.IFS(I35="Block",1),"")} | Y35: {=IFERROR(_xlfn.IFS(I35="Block Received",1),"")} | Z35: {=IFERROR(_xlfn.IFS(I35="Foul",1,I35="Foul Technical",1,I35="Offensive Foul",1),"")} -> 1 | AA35: {=IFERROR(_xlfn.IFS(I35="Foul Received",1),"")} | AB35: {=IFERROR(_xlfn.IFS(I35="Starting lineup",C35,I35="Substitution - In",C35),"")} | AC35: {=IFERROR(_xlfn.IFS(I35="Finishing lineup",C35,I35="Substitution - Out",C35),"")} | AD35: {=IF(AC35<>"",LOOKUP(2,1/((G$2:G34=G35)*(AB$2:AB34<>"")),AB$2:AB34)-AC35,"")} | AE35: {=IF(AC35<>"",LOOKUP(2,1/((G$2:G34=G35)*(AB$2:AB34<>"")),AB$2:AB34)-AC35,"")}
A36: 1 | B36: 35 | C36: 0.0052199074 | D36: =MINUTE(C36) -> 7 | E36: =SECOND(C36) -> 31 | F36: MANRESA | G36: JM08 | H36: =_xlfn.XLOOKUP(G36,'1-Players'!$A$2:$A$27,'1-Players'!$D$2:$D$27,"") -> Álex Reyes | I36: Foul Received | K36: {=IFERROR(_xlfn.IFS(I36="Free Throw",1,I36="2-Point Shot",2,I36="Dunk",2,I36="3-Point Shot",3),"")} | L36: {=IFERROR(_xlfn.IFS(J36="Made",1,J36="Missed",0),"")} | M36: =IFERROR(K36*L36,"") | R36: =IF(J36<>"Made","",IF(I37="Assist","S","N")) | S36: {=IFERROR(_xlfn.IFS(I36="Offensive Rebound",1),"")} | T36: {=IFERROR(_xlfn.IFS(I36="Defensive Rebound",1),"")} | U36: {=IFERROR(_xlfn.IFS(I36="Assist",1),"")} | V36: {=IFERROR(_xlfn.IFS(I36="Turnover",1),"")} | W36: {=IFERROR(_xlfn.IFS(I36="Steal",1),"")} | X36: {=IFERROR(_xlfn.IFS(I36="Block",1),"")} | Y36: {=IFERROR(_xlfn.IFS(I36="Block Received",1),"")} | Z36: {=IFERROR(_xlfn.IFS(I36="Foul",1,I36="Foul Technical",1,I36="Offensive Foul",1),"")} | AA36: {=IFERROR(_xlfn.IFS(I36="Foul Received",1),"")} -> 1 | AB36: {=IFERROR(_xlfn.IFS(I36="Starting lineup",C36,I36="Substitution - In",C36),"")} | AC36: {=IFERROR(_xlfn.IFS(I36="Finishing lineup",C36,I36="Substitution - Out",C36),"")} | AD36: {=IF(AC36<>"",LOOKUP(2,1/((G$2:G35=G36)*(AB$2:AB35<>"")),AB$2:AB35)-AC36,"")} | AE36: {=IF(AC36<>"",LOOKUP(2,1/((G$2:G35=G36)*(AB$2:AB35<>"")),AB$2:AB35)-AC36,"")}
A37: 1 | B37: 36 | C37: 0.0051157407 | D37: =MINUTE(C37) -> 7 | E37: =SECOND(C37) -> 22 | F37: MANRESA | G37: JM08 | H37: =_xlfn.XLOOKUP(G37,'1-Players'!$A$2:$A$27,'1-Players'!$D$2:$D$27,"") -> Álex Reyes | I37: 2-Point Shot | J37: Made | K37: {=IFERROR(_xlfn.IFS(I37="Free Throw",1,I37="2-Point Shot",2,I37="Dunk",2,I37="3-Point Shot",3),"")} -> 2 | L37: {=IFERROR(_xlfn.IFS(J37="Made",1,J37="Missed",0),"")} -> 1 | M37: =IFERROR(K37*L37,"") -> 2 | N37: Floater | O37: MC | P37: 5 | Q37: S | R37: =IF(J37<>"Made","",IF(I38="Assist","S","N")) -> S | S37: {=IFERROR(_xlfn.IFS(I37="Offensive Rebound",1),"")} | T37: {=IFERROR(_xlfn.IFS(I37="Defensive Rebound",1),"")} | U37: {=IFERROR(_xlfn.IFS(I37="Assist",1),"")} | V37: {=IFERROR(_xlfn.IFS(I37="Turnover",1),"")} | W37: {=IFERROR(_xlfn.IFS(I37="Steal",1),"")} | X37: {=IFERROR(_xlfn.IFS(I37="Block",1),"")} | Y37: {=IFERROR(_xlfn.IFS(I37="Block Received",1),"")} | Z37: {=IFERROR(_xlfn.IFS(I37="Foul",1,I37="Foul Technical",1,I37="Offensive Foul",1),"")} | AA37: {=IFERROR(_xlfn.IFS(I37="Foul Received",1),"")} | AB37: {=IFERROR(_xlfn.IFS(I37="Starting lineup",C37,I37="Substitution - In",C37),"")} | AC37: {=IFERROR(_xlfn.IFS(I37="Finishing lineup",C37,I37="Substitution - Out",C37),"")} | AD37: {=IF(AC37<>"",LOOKUP(2,1/((G$2:G36=G37)*(AB$2:AB36<>"")),AB$2:AB36)-AC37,"")} | AE37: {=IF(AC37<>"",LOOKUP(2,1/((G$2:G36=G37)*(AB$2:AB36<>"")),AB$2:AB36)-AC37,"")}
A38: 1 | B38: 37 | C38: 0.0051157407 | D38: =MINUTE(C38) -> 7 | E38: =SECOND(C38) -> 22 | F38: MANRESA | G38: JM02 | H38: =_xlfn.XLOOKUP(G38,'1-Players'!$A$2:$A$27,'1-Players'!$D$2:$D$27,"") -> Hugo Benítez | I38: Assist | K38: {=IFERROR(_xlfn.IFS(I38="Free Throw",1,I38="2-Point Shot",2,I38="Dunk",2,I38="3-Point Shot",3),"")} | L38: {=IFERROR(_xlfn.IFS(J38="Made",1,J38="Missed",0),"")} | M38: =IFERROR(K38*L38,"") | R38: =IF(J38<>"Made","",IF(I39="Assist","S","N")) | S38: {=IFERROR(_xlfn.IFS(I38="Offensive Rebound",1),"")} | T38: {=IFERROR(_xlfn.IFS(I38="Defensive Rebound",1),"")} | U38: {=IFERROR(_xlfn.IFS(I38="Assist",1),"")} -> 1 | V38: {=IFERROR(_xlfn.IFS(I38="Turnover",1),"")} | W38: {=IFERROR(_xlfn.IFS(I38="Steal",1),"")} | X38: {=IFERROR(_xlfn.IFS(I38="Block",1),"")} | Y38: {=IFERROR(_xlfn.IFS(I38="Block Received",1),"")} | Z38: {=IFERROR(_xlfn.IFS(I38="Foul",1,I38="Foul Technical",1,I38="Offensive Foul",1),"")} | AA38: {=IFERROR(_xlfn.IFS(I38="Foul Received",1),"")} | AB38: {=IFERROR(_xlfn.IFS(I38="Starting lineup",C38,I38="Substitution - In",C38),"")} | AC38: {=IFERROR(_xlfn.IFS(I38="Finishing lineup",C38,I38="Substitution - Out",C38),"")} | AD38: {=IF(AC38<>"",LOOKUP(2,1/((G$2:G37=G38)*(AB$2:AB37<>"")),AB$2:AB37)-AC38,"")} | AE38: {=IF(AC38<>"",LOOKUP(2,1/((G$2:G37=G38)*(AB$2:AB37<>"")),AB$2:AB37)-AC38,"")}
A39: 1 | B39: 38 | C39: 0.0048842593 | D39: =MINUTE(C39) -> 7 | E39: =SECOND(C39) -> 2 | F39: MANRESA | G39: JM32 | H39: =_xlfn.XLOOKUP(G39,'1-Players'!$A$2:$A$27,'1-Players'!$D$2:$D$27,"") -> Retin Obasohan | I39: Foul | J39: 2FT | K39: {=IFERROR(_xlfn.IFS(I39="Free Throw",1,I39="2-Point Shot",2,I39="Dunk",2,I39="3-Point Shot",3),"")} | L39: {=IFERROR(_xlfn.IFS(J39="Made",1,J39="Missed",0),"")} | M39: =IFERROR(K39*L39,"") | R39: =IF(J39<>"Made","",IF(I40="Assist","S","N")) | S39: {=IFERROR(_xlfn.IFS(I39="Offensive Rebound",1),"")} | T39: {=IFERROR(_xlfn.IFS(I39="Defensive Rebound",1),"")} | U39: {=IFERROR(_xlfn.IFS(I39="Assist",1),"")} | V39: {=IFERROR(_xlfn.IFS(I39="Turnover",1),"")} | W39: {=IFERROR(_xlfn.IFS(I39="Steal",1),"")} | X39: {=IFERROR(_xlfn.IFS(I39="Block",1),"")} | Y39: {=IFERROR(_xlfn.IFS(I39="Block Received",1),"")} | Z39: {=IFERROR(_xlfn.IFS(I39="Foul",1,I39="Foul Technical",1,I39="Offensive Foul",1),"")} -> 1 | AA39: {=IFERROR(_xlfn.IFS(I39="Foul Received",1),"")} | AB39: {=IFERROR(_xlfn.IFS(I39="Starting lineup",C39,I39="Substitution - In",C39),"")} | AC39: {=IFERROR(_xlfn.IFS(I39="Finishing lineup",C39,I39="Substitution - Out",C39),"")} | AD39: {=IF(AC39<>"",LOOKUP(2,1/((G$2:G38=G39)*(AB$2:AB38<>"")),AB$2:AB38)-AC39,"")} | AE39: {=IF(AC39<>"",LOOKUP(2,1/((G$2:G38=G39)*(AB$2:AB38<>"")),AB$2:AB38)-AC39,"")}
A40: 1 | B40: 39 | C40: 0.0048842593 | D40: =MINUTE(C40) -> 7 | E40: =SECOND(C40) -> 2 | F40: LLEIDA | G40: JL01 | H40: =_xlfn.XLOOKUP(G40,'1-Players'!$A$2:$A$27,'1-Players'!$D$2:$D$27,"") -> James Batemon | I40: Foul Received | K40: {=IFERROR(_xlfn.IFS(I40="Free Throw",1,I40="2-Point Shot",2,I40="Dunk",2,I40="3-Point Shot",3),"")} | L40: {=IFERROR(_xlfn.IFS(J40="Made",1,J40="Missed",0),"")} | M40: =IFERROR(K40*L40,"") | R40: =IF(J40<>"Made","",IF(I41="Assist","S","N")) | S40: {=IFERROR(_xlfn.IFS(I40="Offensive Rebound",1),"")} | T40: {=IFERROR(_xlfn.IFS(I40="Defensive Rebound",1),"")} | U40: {=IFERROR(_xlfn.IFS(I40="Assist",1),"")} | V40: {=IFERROR(_xlfn.IFS(I40="Turnover",1),"")} | W40: {=IFERROR(_xlfn.IFS(I40="Steal",1),"")} | X40: {=IFERROR(_xlfn.IFS(I40="Block",1),"")} | Y40: {=IFERROR(_xlfn.IFS(I40="Block Received",1),"")} | Z40: {=IFERROR(_xlfn.IFS(I40="Foul",1,I40="Foul Technical",1,I40="Offensive Foul",1),"")} | AA40: {=IFERROR(_xlfn.IFS(I40="Foul Received",1),"")} -> 1 | AB40: {=IFERROR(_xlfn.IFS(I40="Starting lineup",C40,I40="Substitution - In",C40),"")} | AC40: {=IFERROR(_xlfn.IFS(I40="Finishing lineup",C40,I40="Substitution - Out",C40),"")} | AD40: {=IF(AC40<>"",LOOKUP(2,1/((G$2:G39=G40)*(AB$2:AB39<>"")),AB$2:AB39)-AC40,"")} | AE40: {=IF(AC40<>"",LOOKUP(2,1/((G$2:G39=G40)*(AB$2:AB39<>"")),AB$2:AB39)-AC40,"")}
...

Sheet 3-Mins_Played_1Q
A1: Jugador_ID | B1: Nombre | C1: Titular | D1: Primera_Entrada | E1: Última_entrada | F1: Primera_Salida | G1: Ultima_Salida | H1: Juega_Algun_Minuto | I1: Acaba_Cuarto | J1: Min_Pista_Jugador_Acaba_Cuarto_Ult_Subint | K1: Min_Pista_Jugador_Resto_Subintervalos | L1: Min_TOTAL | M1: Min_TOTAL_EQUIPO | O1: CUARTO | P1: Acaba_Cuarto_final
A2: JM00 | B2: Kaodirichi Akobundu | C2: NO | D2: =_xlfn.MAXIFS('2-DATASET'!AB:AB,'2-DATASET'!G:G,'1-Players'!A2,'2-DATASET'!A:A,$O$2) -> 0 | E2: =_xlfn.MINIFS('2-DATASET'!AB:AB,'2-DATASET'!G:G,'1-Players'!A2,'2-DATASET'!A:A,$O$2) -> 0 | F2: =_xlfn.MAXIFS('2-DATASET'!AC:AC,'2-DATASET'!G:G,'1-Players'!A2,'2-DATASET'!A:A,$O$2) -> 0 | G2: =_xlfn.MINIFS('2-DATASET'!AC:AC,'2-DATASET'!G:G,'1-Players'!A2,'2-DATASET'!A:A,$O$2) -> 0 | H2: =IF(D2=0,FALSE,TRUE) -> FALSE | I2: =OR(AND(IF(G2>E2,TRUE,FALSE),H2=TRUE),AND(G2=0,H2=TRUE)) -> FALSE | J2: =IF(I2=TRUE,E2,0) -> 0 | K2: =SUMIFS('2-DATASET'!AD:AD,'2-DATASET'!G:G,'3-Mins_Played_1Q'!A2,'2-DATASET'!A:A,$O$2) -> 0 | L2: =J2+K2 -> 0 | O2: 2
A3: JM02 | B3: Hugo Benítez | C3: SI | D3: =_xlfn.MAXIFS('2-DATASET'!AB:AB,'2-DATASET'!G:G,'1-Players'!A3,'2-DATASET'!A:A,$O$2) -> 0 | E3: =_xlfn.MINIFS('2-DATASET'!AB:AB,'2-DATASET'!G:G,'1-Players'!A3,'2-DATASET'!A:A,$O$2) -> 0 | F3: =_xlfn.MAXIFS('2-DATASET'!AC:AC,'2-DATASET'!G:G,'1-Players'!A3) -> 0.0043055556 | G3: =_xlfn.MINIFS('2-DATASET'!AC:AC,'2-DATASET'!G:G,'1-Players'!A3) -> 0.0043055556 | H3: =IF(D3=0,FALSE,TRUE) -> FALSE | I3: =OR(AND(IF(G3>E3,TRUE,FALSE),H3=TRUE),AND(G3=0,H3=TRUE)) -> FALSE | J3: =IF(I3=TRUE,E3,0) -> 0 | K3: =SUMIFS('2-DATASET'!AD:AD,'2-DATASET'!G:G,'3-Mins_Played_1Q'!A3,'2-DATASET'!A:A,$O$2) -> 0 | L3: =J3+K3 -> 0
A4: JM08 | B4: Álex Reyes | C4: SI | D4: =_xlfn.MAXIFS('2-DATASET'!AB:AB,'2-DATASET'!G:G,'1-Players'!A4,'2-DATASET'!A:A,$O$2) -> 0 | E4: =_xlfn.MINIFS('2-DATASET'!AB:AB,'2-DATASET'!G:G,'1-Players'!A4,'2-DATASET'!A:A,$O$2) -> 0 | F4: =_xlfn.MAXIFS('2-DATASET'!AC:AC,'2-DATASET'!G:G,'1-Players'!A4) -> 0.0031828704 | G4: =_xlfn.MINIFS('2-DATASET'!AC:AC,'2-DATASET'!G:G,'1-Players'!A4) -> 0.0031828704 | H4: =IF(D4=0,FALSE,TRUE) -> FALSE | I4: =OR(AND(IF(G4>E4,TRUE,FALSE),H4=TRUE),AND(G4=0,H4=TRUE)) -> FALSE | J4: =IF(I4=TRUE,E4,0) -> 0 | K4: =SUMIFS('2-DATASET'!AD:AD,'2-DATASET'!G:G,'3-Mins_Played_1Q'!A4,'2-DATASET'!A:A,$O$2) -> 0 | L4: =J4+K4 -> 0
A5: JM11 | B5: Agustín Ubal | C5: NO | D5: =_xlfn.MAXIFS('2-DATASET'!AB:AB,'2-DATASET'!G:G,'1-Players'!A5,'2-DATASET'!A:A,$O$2) -> 0.0069444444 | E5: =_xlfn.MINIFS('2-DATASET'!AB:AB,'2-DATASET'!G:G,'1-Players'!A5,'2-DATASET'!A:A,$O$2) -> 0.0069444444 | F5: =_xlfn.MAXIFS('2-DATASET'!AC:AC,'2-DATASET'!G:G,'1-Players'!A5) -> 0 | G5: =_xlfn.MINIFS('2-DATASET'!AC:AC,'2-DATASET'!G:G,'1-Players'!A5) -> 0 | H5: =IF(D5=0,FALSE,TRUE) -> TRUE | I5: =OR(AND(IF(G5>E5,TRUE,FALSE),H5=TRUE),AND(G5=0,H5=TRUE)) -> TRUE | J5: =IF(I5=TRUE,E5,0) -> 0.0069444444 | K5: =SUMIFS('2-DATASET'!AD:AD,'2-DATASET'!G:G,'3-Mins_Played_1Q'!A5,'2-DATASET'!A:A,$O$2) -> 0 | L5: =J5+K5 -> 0.0069444444
A6: JM12 | B6: Marcis Steinbergs | C6: SI | D6: =_xlfn.MAXIFS('2-DATASET'!AB:AB,'2-DATASET'!G:G,'1-Players'!A6,'2-DATASET'!A:A,$O$2) -> 0.0069444444 | E6: =_xlfn.MINIFS('2-DATASET'!AB:AB,'2-DATASET'!G:G,'1-Players'!A6,'2-DATASET'!A:A,$O$2) -> 0.0069444444 | F6: =_xlfn.MAXIFS('2-DATASET'!AC:AC,'2-DATASET'!G:G,'1-Players'!A6) -> 0.0046990741 | G6: =_xlfn.MINIFS('2-DATASET'!AC:AC,'2-DATASET'!G:G,'1-Players'!A6) -> 0 | H6: =IF(D6=0,FALSE,TRUE) -> TRUE | I6: =OR(AND(IF(G6>E6,TRUE,FALSE),H6=TRUE),AND(G6=0,H6=TRUE)) -> TRUE | J6: =IF(I6=TRUE,E6,0) -> 0.0069444444 | K6: =SUMIFS('2-DATASET'!AD:AD,'2-DATASET'!G:G,'3-Mins_Played_1Q'!A6,'2-DATASET'!A:A,$O$2) -> 0 | L6: =J6+K6 -> 0.0069444444
A7: JM18 | B7: Gustav Knudsen | C7: NO | D7: =_xlfn.MAXIFS('2-DATASET'!AB:AB,'2-DATASET'!G:G,'1-Players'!A7,'2-DATASET'!A:A,$O$2) -> 0 | E7: =_xlfn.MINIFS('2-DATASET'!AB:AB,'2-DATASET'!G:G,'1-Players'!A7,'2-DATASET'!A:A,$O$2) -> 0 | F7: =_xlfn.MAXIFS('2-DATASET'!AC:AC,'2-DATASET'!G:G,'1-Players'!A7) -> 0 | G7: =_xlfn.MINIFS('2-DATASET'!AC:AC,'2-DATASET'!G:G,'1-Players'!A7) -> 0 | H7: =IF(D7=0,FALSE,TRUE) -> FALSE | I7: =OR(AND(IF(G7>E7,TRUE,FALSE),H7=TRUE),AND(G7=0,H7=TRUE)) -> FALSE | J7: =IF(I7=TRUE,E7,0) -> 0 | K7: =SUMIFS('2-DATASET'!AD:AD,'2-DATASET'!G:G,'3-Mins_Played_1Q'!A7,'2-DATASET'!A:A,$O$2) -> 0 | L7: =J7+K7 -> 0
A8: JM19 | B8: Louis Olinde | C8: NO | D8: =_xlfn.MAXIFS('2-DATASET'!AB:AB,'2-DATASET'!G:G,'1-Players'!A8,'2-DATASET'!A:A,$O$2) -> 0 | E8: =_xlfn.MINIFS('2-DATASET'!AB:AB,'2-DATASET'!G:G,'1-Players'!A8,'2-DATASET'!A:A,$O$2) -> 0 | F8: =_xlfn.MAXIFS('2-DATASET'!AC:AC,'2-DATASET'!G:G,'1-Players'!A8) -> 0.0015509259 | G8: =_xlfn.MINIFS('2-DATASET'!AC:AC,'2-DATASET'!G:G,'1-Players'!A8) -> 0.0015509259 | H8: =IF(D8=0,FALSE,TRUE) -> FALSE | I8: =OR(AND(IF(G8>E8,TRUE,FALSE),H8=TRUE),AND(G8=0,H8=TRUE)) -> FALSE | J8: =IF(I8=TRUE,E8,0) -> 0 | K8: =SUMIFS('2-DATASET'!AD:AD,'2-DATASET'!G:G,'3-Mins_Played_1Q'!A8,'2-DATASET'!A:A,$O$2) -> 0 | L8: =J8+K8 -> 0
